Workbook

Sheet Accueil
B1: AéroAtlas Composites SARL — DOSSIER DE CLÔTURE 2025 (CGNC)
B2: ="Société : "&Accueil!$C$8&" │ Exercice : "&Accueil!$C$11&" │ Date d'arrêté : "&Accueil!$C$12&" │ Responsable : "&Accueil!$C$15 -> Société : AéroAtlas Composites SARL │ Exercice : 2025 │ Date d'arrêté : 31/12/2025 │ Responsable : Karim El Fassi (DAF)
C4: Balance → CPC → ESG → Reporting KPI → Dashboard │ Document préparé pour l'expert-auditeur et les investisseurs
B5: ⚠ DONNÉES ILLUSTRATIVES — société et chiffres fictifs, à usage de démonstration du modèle de clôture
B7: IDENTITÉ DE L'ENTREPRISE
B8: Nom de l'entreprise | C8: AéroAtlas Composites SARL
B9: Forme juridique / Capital | C9: SARL au capital de 50 000 000,00 MAD
B10: Secteur | C10: Aéronautique — sous-traitance de rang 2 (usinage, composites, câblage)
B11: Exercice | C11: 2025
B12: Date d'arrêté | C12: 31/12/2025
B13: Date d'édition | C13: 03/10/2026
B14: Département | C14: Direction Administrative & Financière
B15: Responsable département | C15: Karim El Fassi (DAF)
B16: Site | C16: Midparc — zone d'accélération industrielle, Nouaceur (Casablanca)
B17: Référentiel | C17: CGNC — CPC / ESG modèles normaux ; CGI (IS 20 % — ZAI)
B18: Profil commercial | C18: 70 % du CA à l'export (facturé hors TVA) — 30 % local (TVA 20 %)
B20: SOMMAIRE
B21: Onglet | C21: Contenu | D21: Accès
B22: 1. Balance | C22: Balance générale CGNC classes 1 à 7, Déc. N-1 + 12 mois, contrôle d'équilibre mensuel | D22: Ouvrir ▸
B23: 2. CPC | C23: Compte de produits et charges détaillé (I à XVI), calcul automatique mensuel par racine de compte | D23: Ouvrir ▸
B24: 3. ESG | C24: État des soldes de gestion : TFR (marge → RN) et CAF / autofinancement, 12 mois | D24: Ouvrir ▸
B25: 4. Reporting | C25: Élasticité CA/REX, 17 KPI avec benchmark sectoriel, statuts colorés, commentaires et recommandations chiffrés | D25: Ouvrir ▸
B26: 5. DASHBOARD | C26: Vue direction générale : 4 cartes (CA, DSO, DPO, croissance RN) et 4 graphiques de tendance | D26: Ouvrir ▸
B27: 6. Lecture | C27: Dictionnaire des indicateurs en langage simple + glossaire | D27: Ouvrir ▸
B29: CONTRÔLES DE COHÉRENCE (calculés en temps réel)
B30: Balance équilibrée (13 colonnes) | C30: =IF(SUMPRODUCT(ABS(Balance!D5:P5))<0.01,"✔ Conforme","✖ À vérifier") -> ✔ Conforme
B31: Résultat CPC = Balance (13 colonnes) | C31: =IF(SUMPRODUCT(ABS(CPC!D66:P66))<0.01,"✔ Conforme","✖ À vérifier") -> ✔ Conforme
B32: RN et REX : ESG = CPC (13 colonnes) | C32: =IF(SUMPRODUCT(ABS(ESG!D47:P47))<0.01,"✔ Conforme","✖ À vérifier") -> ✔ Conforme
B33: Chiffre d'affaires 2025 | C33: =CPC!Q11 -> 142000000
B34: Résultat net 2025 | C34: =CPC!Q60 -> 10960000
B35: Capacité d'autofinancement 2025 | C35: =ESG!Q43 -> 19590000
B37: MODE D'EMPLOI
B38: 1. Balance : seule zone de saisie (chiffres en bleu). Pour utiliser une vraie balance, coller les comptes CGNC (4 chiffres) en colonne B, les intitulés en C et les montants signés (Débit +, Crédit −) en D:P, lignes 7 à 400.
B39: 2. Convention : classes 1 à 5 = soldes de fin de mois ; classes 6 et 7 = mouvements du mois. La colonne Déc. N-1 sert de référence pour les variations de janvier.
B40: 3. Vérifier que la ligne « Contrôle équilibre » de la Balance et les contrôles ci-dessus sont tous verts avant toute lecture.
B41: 4. CPC et ESG se calculent automatiquement par racine de compte : aucune saisie, aucun chiffre en dur.
B42: 5. Reporting : choisir le mois dans la cellule « Mois sélectionné » (liste déroulante). Le tableau des KPI, les statuts et les commentaires chiffrés se mettent à jour.
B43: 6. Les seuils du benchmark et les hypothèses (part export, TVA, jours/mois) sont modifiables dans le Reporting (cellules en bleu sur fond doré).
B44: 7. DASHBOARD : choisir le mois dans son propre sélecteur ; les 4 cartes affichent la valeur, l'évolution vs mois précédent et le statut. Les graphiques montrent les 12 mois.
B45: 8. Couleurs : vert = conforme │ bleu = neutre │ orange = vigilance │ rouge = alerte │ « — » = calcul impossible │ « n.s. » = non significatif. Définitions : onglet Lecture.

Sheet Balance
B1: BALANCE GÉNÉRALE MENSUELLE — CGNC (classes 1 à 7)
B2: ="Société : "&Accueil!$C$8&" │ Exercice : "&Accueil!$C$11&" │ Date d'arrêté : "&Accueil!$C$12&" │ Responsable : "&Accueil!$C$15 -> Société : AéroAtlas Composites SARL │ Exercice : 2025 │ Date d'arrêté : 31/12/2025 │ Responsable : Karim El Fassi (DAF)
B4: ← Accueil | C4: Convention : Débit = +, Crédit = − │ Classes 1 à 5 : soldes de fin de mois │ Classes 6 et 7 : mouvements du mois │ Déc. N-1 = référence
C5: CONTRÔLE ÉQUILIBRE (doit être = 0) | D5: =ROUND(SUMPRODUCT(($B$7:$B$400<>"")*D$7:D$400),2) -> 0 | E5: =ROUND(SUMPRODUCT(($B$7:$B$400<>"")*E$7:E$400),2) -> 0 | F5: =ROUND(SUMPRODUCT(($B$7:$B$400<>"")*F$7:F$400),2) -> 0 | G5: =ROUND(SUMPRODUCT(($B$7:$B$400<>"")*G$7:G$400),2) -> 0 | H5: =ROUND(SUMPRODUCT(($B$7:$B$400<>"")*H$7:H$400),2) -> 0 | I5: =ROUND(SUMPRODUCT(($B$7:$B$400<>"")*I$7:I$400),2) -> 0 | J5: =ROUND(SUMPRODUCT(($B$7:$B$400<>"")*J$7:J$400),2) -> 0 | K5: =ROUND(SUMPRODUCT(($B$7:$B$400<>"")*K$7:K$400),2) -> 0 | ... P5: =ROUND(SUMPRODUCT(($B$7:$B$400<>"")*P$7:P$400),2) -> 0
B6: N° compte | C6: Intitulé du compte (CGNC) | D6: Déc. N-1 | E6: Janvier | F6: Février | G6: Mars | H6: Avril | I6: Mai | J6: Juin | K6: Juillet | L6: Août | M6: Septembre | N6: Octobre | O6: Novembre | P6: Décembre
C7: CLASSE 1 — COMPTES DE FINANCEMENT PERMANENT (sous-total) | D7: =SUM(D8:D18) -> -125140000 | E7: =SUM(E8:E18) -> -1.2478684e+08 | F7: =SUM(F8:F18) -> -1.2496251e+08 | G7: =SUM(G8:G18) -> -1.254692e+08 | H7: =SUM(H8:H18) -> -1.2597533e+08 | I7: =SUM(I8:I18) -> -1.2627093e+08 | J7: =SUM(J8:J18) -> -1.2714189e+08 | K7: =SUM(K8:K18) -> -1.2826377e+08 | ... P7: =SUM(P8:P18) -> -1.2865043e+08
B8: 1111 | C8: Capital social | D8: -50000000 | E8: -50000000 | F8: -50000000 | G8: -50000000 | H8: -50000000 | I8: -50000000 | J8: -50000000 | K8: -50000000 | L8: -50000000 | M8: -50000000 | N8: -50000000 | O8: -50000000 | P8: -50000000
B9: 1140 | C9: Réserve légale | D9: -5000000 | E9: -5000000 | F9: -5000000 | G9: -5000000 | H9: -5000000 | I9: -5000000 | J9: -5000000 | K9: -5000000 | L9: -5000000 | M9: -5000000 | N9: -5000000 | O9: -5000000 | P9: -5000000
B10: 1161 | C10: Report à nouveau (solde créditeur) | D10: -10000000 | E10: -10000000 | F10: -10000000 | G10: -10000000 | H10: -10000000 | I10: -10000000 | J10: -18806840 | K10: -18806840 | L10: -18806840 | M10: -18806840 | N10: -18806840 | O10: -18806840 | P10: -18806840
B11: 1181 | C11: Résultats nets en instance d'affectation (solde créditeur) | D11: 0 | E11: -8806839.5 | F11: -8806839.5 | G11: -8806839.5 | H11: -8806839.5 | I11: -8806839.5 | J11: 0 | K11: 0 | L11: 0 | M11: 0 | N11: 0 | O11: 0 | P11: 0
B12: 1191 | C12: Résultat net de l'exercice (cumul à fin du mois précédent) | D12: -8600000 | E12: 0 | F12: -735670.37 | G12: -1802358.1 | H12: -2868491 | I12: -3724089.5 | J12: -5155051.5 | K12: -6836934.6 | L12: -8021757 | M12: -7624272.5 | N12: -7982071.9 | O12: -9140621.9 | P12: -10023589
B13: 1311 | C13: Subventions d'investissement reçues | D13: -1500000 | E13: -1500000 | F13: -1500000 | G13: -1500000 | H13: -1500000 | I13: -1500000 | J13: -1500000 | K13: -1500000 | L13: -1500000 | M13: -1500000 | N13: -1500000 | O13: -1500000 | P13: -1500000
B14: 1319 | C14: Subventions d'investissement inscrites au CPC | D14: 360000 | E14: 370000 | F14: 380000 | G14: 390000 | H14: 400000 | I14: 410000 | J14: 420000 | K14: 430000 | L14: 440000 | M14: 450000 | N14: 460000 | O14: 470000 | P14: 480000
B15: 1481 | C15: Emprunts auprès des établissements de crédit | D15: -50000000 | E15: -49450000 | F15: -48900000 | G15: -48350000 | H15: -47800000 | I15: -47250000 | J15: -46700000 | K15: -46150000 | L15: -45600000 | M15: -45050000 | N15: -44500000 | O15: -43950000 | P15: -43400000
B16: 1488 | C16: Dettes de financement diverses | D16: 0 | E16: 0 | F16: 0 | G16: 0 | H16: 0 | I16: 0 | J16: 0 | K16: 0 | L16: 0 | M16: 0 | N16: 0 | O16: 0 | P16: 0
B17: 1511 | C17: Provisions pour litiges | D17: -400000 | E17: -400000 | F17: -400000 | G17: -400000 | H17: -400000 | I17: -400000 | J17: -400000 | K17: -400000 | L17: -400000 | M17: -400000 | N17: -400000 | O17: -400000 | P17: -400000
B18: 1516 | C18: Provisions pour pertes de change | D18: 0 | E18: 0 | F18: 0 | G18: 0 | H18: 0 | I18: 0 | J18: 0 | K18: 0 | L18: 0 | M18: 0 | N18: 0 | O18: 0 | P18: 0
C19: CLASSE 2 — COMPTES D'ACTIF IMMOBILISÉ (sous-total) | D19: =SUM(D20:D35) -> 97000000 | E19: =SUM(E20:E35) -> 96266667 | F19: =SUM(F20:F35) -> 95533333 | G19: =SUM(G20:G35) -> 94800000 | H19: =SUM(H20:H35) -> 98566667 | I19: =SUM(I20:I35) -> 97833333 | J19: =SUM(J20:J35) -> 97100000 | K19: =SUM(K20:K35) -> 96366667 | ... P19: =SUM(P20:P35) -> 94450000
B20: 2121 | C20: Frais d'acquisition des immobilisations | D20: 2000000 | E20: 2000000 | F20: 2000000 | G20: 2000000 | H20: 2000000 | I20: 2000000 | J20: 2000000 | K20: 2000000 | L20: 2000000 | M20: 2000000 | N20: 2000000 | O20: 2000000 | P20: 2000000
B21: 2220 | C21: Brevets, marques, droits et valeurs similaires | D21: 1800000 | E21: 1800000 | F21: 1800000 | G21: 1800000 | H21: 1800000 | I21: 1800000 | J21: 1800000 | K21: 1800000 | L21: 1800000 | M21: 1800000 | N21: 1800000 | O21: 1800000 | P21: 1800000
B22: 2310 | C22: Terrains | D22: 6000000 | E22: 6000000 | F22: 6000000 | G22: 6000000 | H22: 6000000 | I22: 6000000 | J22: 6000000 | K22: 6000000 | L22: 6000000 | M22: 6000000 | N22: 6000000 | O22: 6000000 | P22: 6000000
B23: 2321 | C23: Bâtiments | D23: 28000000 | E23: 28000000 | F23: 28000000 | G23: 28000000 | H23: 28000000 | I23: 28000000 | J23: 28000000 | K23: 28000000 | L23: 28000000 | M23: 28000000 | N23: 28000000 | O23: 28000000 | P23: 28000000
B24: 2332 | C24: Matériel et outillage | D24: 108000000 | E24: 108000000 | F24: 108000000 | G24: 108000000 | H24: 112500000 | I24: 112500000 | J24: 112500000 | K24: 112500000 | L24: 112500000 | M24: 114000000 | N24: 114000000 | O24: 114000000 | P24: 114000000
B25: 2340 | C25: Matériel de transport | D25: 3000000 | E25: 3000000 | F25: 3000000 | G25: 3000000 | H25: 3000000 | I25: 3000000 | J25: 3000000 | K25: 3000000 | L25: 3000000 | M25: 3000000 | N25: 1800000 | O25: 1800000 | P25: 1800000
B26: 2351 | C26: Mobilier de bureau | D26: 1200000 | E26: 1200000 | F26: 1200000 | G26: 1200000 | H26: 1200000 | I26: 1200000 | J26: 1200000 | K26: 1200000 | L26: 1200000 | M26: 1200000 | N26: 1200000 | O26: 1200000 | P26: 1200000
B27: 2355 | C27: Matériel informatique | D27: 2400000 | E27: 2400000 | F27: 2400000 | G27: 2400000 | H27: 2400000 | I27: 2400000 | J27: 2400000 | K27: 2400000 | L27: 2400000 | M27: 2900000 | N27: 2900000 | O27: 2900000 | P27: 2900000
B28: 2397 | C28: Avances et acomptes versés sur commandes d'immobilisations corporelles | D28: 0 | E28: 0 | F28: 0 | G28: 0 | H28: 0 | I28: 0 | J28: 0 | K28: 0 | L28: 0 | M28: 0 | N28: 0 | O28: 0 | P28: 0
B29: 2486 | C29: Dépôts et cautionnements versés | D29: 600000 | E29: 600000 | F29: 600000 | G29: 600000 | H29: 600000 | I29: 600000 | J29: 600000 | K29: 600000 | L29: 600000 | M29: 600000 | N29: 600000 | O29: 600000 | P29: 600000
B30: 2812 | C30: Amortissements des charges à répartir | D30: -800000 | E30: -833333.33 | F30: -866666.66 | G30: -899999.99 | H30: -933333.32 | I30: -966666.65 | J30: -999999.98 | K30: -1033333.3 | L30: -1066666.6 | M30: -1100000 | N30: -1133333.3 | O30: -1166666.6 | P30: -1200000
B31: 2822 | C31: Amortissements des brevets, marques, droits et valeurs similaires | D31: -600000 | E31: -625000 | F31: -650000 | G31: -675000 | H31: -700000 | I31: -725000 | J31: -750000 | K31: -775000 | L31: -800000 | M31: -825000 | N31: -850000 | O31: -875000 | P31: -900000
... B35: 2835 | C35: Amortissements du mobilier, matériel de bureau et aménagements divers | D35: -1500000 | E35: -1548333.3 | F35: -1596666.7 | G35: -1645000 | H35: -1693333.3 | I35: -1741666.7 | J35: -1790000 | K35: -1838333.3 | L35: -1886666.7 | M35: -1935000 | N35: -1983333.3 | O35: -2031666.7 | P35: -2080000
C36: CLASSE 3 — COMPTES D'ACTIF CIRCULANT (HORS TRÉSORERIE) (sous-total) | D36: =SUM(D37:D51) -> 51961368 | E36: =SUM(E37:E51) -> 51017864 | F36: =SUM(F37:F51) -> 50828439 | G36: =SUM(G37:G51) -> 50968015 | H36: =SUM(H37:H51) -> 51769296 | I36: =SUM(I37:I51) -> 52926022 | J36: =SUM(J37:J51) -> 54304844 | K36: =SUM(K37:K51) -> 54080248 | ... P36: =SUM(P37:P51) -> 56600208
B37: 3111 | C37: Marchandises | D37: 0 | E37: 0 | F37: 0 | G37: 0 | H37: 0 | I37: 0 | J37: 0 | K37: 0 | L37: 0 | M37: 0 | N37: 0 | O37: 0 | P37: 0
B38: 3121 | C38: Matières premières | D38: 7744000 | E38: 7920000 | F38: 8184000 | G38: 8448000 | H38: 8272000 | I38: 8360000 | J38: 8536000 | K38: 8712000 | L38: 9152000 | M38: 8624000 | N38: 8360000 | O38: 8184000 | P38: 8008000
B39: 3122 | C39: Matières et fournitures consommables | D39: 1056000 | E39: 1080000 | F39: 1116000 | G39: 1152000 | H39: 1128000 | I39: 1140000 | J39: 1164000 | K39: 1188000 | L39: 1248000 | M39: 1176000 | N39: 1140000 | O39: 1116000 | P39: 1092000
B40: 3131 | C40: Biens en cours | D40: 3850000 | E40: 3905000 | F40: 4015000 | G40: 4125000 | H40: 4180000 | I40: 4290000 | J40: 4345000 | K40: 4510000 | L40: 4620000 | M40: 4565000 | N40: 4620000 | O40: 4730000 | P40: 4510000
B41: 3151 | C41: Produits finis | D41: 3150000 | E41: 3195000 | F41: 3285000 | G41: 3375000 | H41: 3420000 | I41: 3510000 | J41: 3555000 | K41: 3690000 | L41: 3780000 | M41: 3735000 | N41: 3780000 | O41: 3870000 | P41: 3690000
B42: 3411 | C42: Fournisseurs - avances et acomptes versés sur commandes d'exploitation | D42: 792249.71 | E42: 819650.44 | F42: 787069.34 | G42: 749215.23 | H42: 725600.68 | I42: 807202.46 | J42: 729724.43 | K42: 770049.34 | L42: 748182.08 | M42: 813619.46 | N42: 831407.01 | O42: 862946.23 | P42: 806093.01
B43: 3421 | C43: Clients | D43: 28719640 | E43: 27598160 | F43: 27061800 | G43: 28280800 | H43: 29158480 | I43: 29938640 | J43: 30572520 | K43: 29938640 | L43: 24770080 | M43: 24672560 | N43: 27890720 | O43: 30377480 | P43: 31986560
B44: 3424 | C44: Clients douteux ou litigieux | D44: 1400000 | E44: 1400000 | F44: 1400000 | G44: 1400000 | H44: 1400000 | I44: 1400000 | J44: 1400000 | K44: 1400000 | L44: 1400000 | M44: 1400000 | N44: 1400000 | O44: 1400000 | P44: 1400000
...

Sheet CPC
B1: COMPTE DE PRODUITS ET CHARGES (CPC) — MODÈLE CGNC DÉTAILLÉ
B2: ="Société : "&Accueil!$C$8&" │ Exercice : "&Accueil!$C$11&" │ Date d'arrêté : "&Accueil!$C$12&" │ Responsable : "&Accueil!$C$15 -> Société : AéroAtlas Composites SARL │ Exercice : 2025 │ Date d'arrêté : 31/12/2025 │ Responsable : Karim El Fassi (DAF)
B4: ← Accueil | C4: Calcul automatique depuis l'onglet Balance, par racine de compte, mois par mois │ Montants en MAD │ Déc. N-1 = référence (hors total)
B6: Rubriques | C6: Comptes | D6: Déc. N-1 | E6: Janvier | F6: Février | G6: Mars | H6: Avril | I6: Mai | J6: Juin | K6: Juillet | L6: Août | M6: Septembre | N6: Octobre | O6: Novembre | P6: Décembre | Q6: TOTAL 2025
B7: EXPLOITATION
B8: I PRODUITS D'EXPLOITATION
B9: Ventes de marchandises (en l'état) | C9: 711 | D9: =-SUMPRODUCT(((LEFT(Balance!$B$7:$B$400,3)="711"))*Balance!D$7:D$400) -> 48759.93 | E9: =-SUMPRODUCT(((LEFT(Balance!$B$7:$B$400,3)="711"))*Balance!E$7:E$400) -> 46033.13 | F9: =-SUMPRODUCT(((LEFT(Balance!$B$7:$B$400,3)="711"))*Balance!F$7:F$400) -> 47260.36 | G9: =-SUMPRODUCT(((LEFT(Balance!$B$7:$B$400,3)="711"))*Balance!G$7:G$400) -> 51367.28 | H9: =-SUMPRODUCT(((LEFT(Balance!$B$7:$B$400,3)="711"))*Balance!H$7:H$400) -> 48774.59 | I9: =-SUMPRODUCT(((LEFT(Balance!$B$7:$B$400,3)="711"))*Balance!I$7:I$400) -> 54751.3 | J9: =-SUMPRODUCT(((LEFT(Balance!$B$7:$B$400,3)="711"))*Balance!J$7:J$400) -> 54310.72 | K9: =-SUMPRODUCT(((LEFT(Balance!$B$7:$B$400,3)="711"))*Balance!K$7:K$400) -> 47737.13 | ... P9: =-SUMPRODUCT(((LEFT(Balance!$B$7:$B$400,3)="711"))*Balance!P$7:P$400) -> 58145.28 | Q9: =SUM(E9:P9) -> 597614.05
B10: Ventes de biens et services produits | C10: 712 | D10: =-SUMPRODUCT(((LEFT(Balance!$B$7:$B$400,3)="712"))*Balance!D$7:D$400) -> 11451240 | E10: =-SUMPRODUCT(((LEFT(Balance!$B$7:$B$400,3)="712"))*Balance!E$7:E$400) -> 10753967 | F10: =-SUMPRODUCT(((LEFT(Balance!$B$7:$B$400,3)="712"))*Balance!F$7:F$400) -> 11152740 | G10: =-SUMPRODUCT(((LEFT(Balance!$B$7:$B$400,3)="712"))*Balance!G$7:G$400) -> 12348633 | H10: =-SUMPRODUCT(((LEFT(Balance!$B$7:$B$400,3)="712"))*Balance!H$7:H$400) -> 11851225 | I10: =-SUMPRODUCT(((LEFT(Balance!$B$7:$B$400,3)="712"))*Balance!I$7:I$400) -> 12545249 | J10: =-SUMPRODUCT(((LEFT(Balance!$B$7:$B$400,3)="712"))*Balance!J$7:J$400) -> 12745689 | K10: =-SUMPRODUCT(((LEFT(Balance!$B$7:$B$400,3)="712"))*Balance!K$7:K$400) -> 11552263 | ... P10: =-SUMPRODUCT(((LEFT(Balance!$B$7:$B$400,3)="712"))*Balance!P$7:P$400) -> 14041855 | Q10: =SUM(E10:P10) -> 1.4140239e+08
B11: Chiffre d'affaires | C11: 711+712 | D11: =D9+D10 -> 11500000 | E11: =E9+E10 -> 10800000 | F11: =F9+F10 -> 11200000 | G11: =G9+G10 -> 12400000 | H11: =H9+H10 -> 11900000 | I11: =I9+I10 -> 12600000 | J11: =J9+J10 -> 12800000 | K11: =K9+K10 -> 11600000 | ... P11: =P9+P10 -> 14100000 | Q11: =SUM(E11:P11) -> 142000000
B12: Variation de stocks de produits (±) | C12: 713 | D12: =-SUMPRODUCT(((LEFT(Balance!$B$7:$B$400,3)="713"))*Balance!D$7:D$400) -> 100000 | E12: =-SUMPRODUCT(((LEFT(Balance!$B$7:$B$400,3)="713"))*Balance!E$7:E$400) -> 100000 | F12: =-SUMPRODUCT(((LEFT(Balance!$B$7:$B$400,3)="713"))*Balance!F$7:F$400) -> 200000 | G12: =-SUMPRODUCT(((LEFT(Balance!$B$7:$B$400,3)="713"))*Balance!G$7:G$400) -> 200000 | H12: =-SUMPRODUCT(((LEFT(Balance!$B$7:$B$400,3)="713"))*Balance!H$7:H$400) -> 100000 | I12: =-SUMPRODUCT(((LEFT(Balance!$B$7:$B$400,3)="713"))*Balance!I$7:I$400) -> 200000 | J12: =-SUMPRODUCT(((LEFT(Balance!$B$7:$B$400,3)="713"))*Balance!J$7:J$400) -> 100000 | K12: =-SUMPRODUCT(((LEFT(Balance!$B$7:$B$400,3)="713"))*Balance!K$7:K$400) -> 300000 | ... P12: =-SUMPRODUCT(((LEFT(Balance!$B$7:$B$400,3)="713"))*Balance!P$7:P$400) -> -400000 | Q12: =SUM(E12:P12) -> 1200000
B13: Immobilisations produites par l'entreprise pour elle-même | C13: 714 | D13: =-SUMPRODUCT(((LEFT(Balance!$B$7:$B$400,3)="714"))*Balance!D$7:D$400) -> 0 | E13: =-SUMPRODUCT(((LEFT(Balance!$B$7:$B$400,3)="714"))*Balance!E$7:E$400) -> 0 | F13: =-SUMPRODUCT(((LEFT(Balance!$B$7:$B$400,3)="714"))*Balance!F$7:F$400) -> 0 | G13: =-SUMPRODUCT(((LEFT(Balance!$B$7:$B$400,3)="714"))*Balance!G$7:G$400) -> 0 | H13: =-SUMPRODUCT(((LEFT(Balance!$B$7:$B$400,3)="714"))*Balance!H$7:H$400) -> 0 | I13: =-SUMPRODUCT(((LEFT(Balance!$B$7:$B$400,3)="714"))*Balance!I$7:I$400) -> 0 | J13: =-SUMPRODUCT(((LEFT(Balance!$B$7:$B$400,3)="714"))*Balance!J$7:J$400) -> 0 | K13: =-SUMPRODUCT(((LEFT(Balance!$B$7:$B$400,3)="714"))*Balance!K$7:K$400) -> 0 | ... P13: =-SUMPRODUCT(((LEFT(Balance!$B$7:$B$400,3)="714"))*Balance!P$7:P$400) -> 0 | Q13: =SUM(E13:P13) -> 0
B14: Subventions d'exploitation | C14: 716 | D14: =-SUMPRODUCT(((LEFT(Balance!$B$7:$B$400,3)="716"))*Balance!D$7:D$400) -> 0 | E14: =-SUMPRODUCT(((LEFT(Balance!$B$7:$B$400,3)="716"))*Balance!E$7:E$400) -> 0 | F14: =-SUMPRODUCT(((LEFT(Balance!$B$7:$B$400,3)="716"))*Balance!F$7:F$400) -> 0 | G14: =-SUMPRODUCT(((LEFT(Balance!$B$7:$B$400,3)="716"))*Balance!G$7:G$400) -> 0 | H14: =-SUMPRODUCT(((LEFT(Balance!$B$7:$B$400,3)="716"))*Balance!H$7:H$400) -> 0 | I14: =-SUMPRODUCT(((LEFT(Balance!$B$7:$B$400,3)="716"))*Balance!I$7:I$400) -> 0 | J14: =-SUMPRODUCT(((LEFT(Balance!$B$7:$B$400,3)="716"))*Balance!J$7:J$400) -> 250000 | K14: =-SUMPRODUCT(((LEFT(Balance!$B$7:$B$400,3)="716"))*Balance!K$7:K$400) -> 0 | ... P14: =-SUMPRODUCT(((LEFT(Balance!$B$7:$B$400,3)="716"))*Balance!P$7:P$400) -> 250000 | Q14: =SUM(E14:P14) -> 500000
B15: Autres produits d'exploitation | C15: 718 | D15: =-SUMPRODUCT(((LEFT(Balance!$B$7:$B$400,3)="718"))*Balance!D$7:D$400) -> 41666.67 | E15: =-SUMPRODUCT(((LEFT(Balance!$B$7:$B$400,3)="718"))*Balance!E$7:E$400) -> 41666.67 | F15: =-SUMPRODUCT(((LEFT(Balance!$B$7:$B$400,3)="718"))*Balance!F$7:F$400) -> 41666.67 | G15: =-SUMPRODUCT(((LEFT(Balance!$B$7:$B$400,3)="718"))*Balance!G$7:G$400) -> 41666.67 | H15: =-SUMPRODUCT(((LEFT(Balance!$B$7:$B$400,3)="718"))*Balance!H$7:H$400) -> 41666.67 | I15: =-SUMPRODUCT(((LEFT(Balance!$B$7:$B$400,3)="718"))*Balance!I$7:I$400) -> 41666.67 | J15: =-SUMPRODUCT(((LEFT(Balance!$B$7:$B$400,3)="718"))*Balance!J$7:J$400) -> 41666.67 | K15: =-SUMPRODUCT(((LEFT(Balance!$B$7:$B$400,3)="718"))*Balance!K$7:K$400) -> 41666.67 | ... P15: =-SUMPRODUCT(((LEFT(Balance!$B$7:$B$400,3)="718"))*Balance!P$7:P$400) -> 41666.67 | Q15: =SUM(E15:P15) -> 500000.04
B16: Reprises d'exploitation ; transferts de charges | C16: 719 | D16: =-SUMPRODUCT(((LEFT(Balance!$B$7:$B$400,3)="719"))*Balance!D$7:D$400) -> 0 | E16: =-SUMPRODUCT(((LEFT(Balance!$B$7:$B$400,3)="719"))*Balance!E$7:E$400) -> 0 | F16: =-SUMPRODUCT(((LEFT(Balance!$B$7:$B$400,3)="719"))*Balance!F$7:F$400) -> 0 | G16: =-SUMPRODUCT(((LEFT(Balance!$B$7:$B$400,3)="719"))*Balance!G$7:G$400) -> 150000 | H16: =-SUMPRODUCT(((LEFT(Balance!$B$7:$B$400,3)="719"))*Balance!H$7:H$400) -> 0 | I16: =-SUMPRODUCT(((LEFT(Balance!$B$7:$B$400,3)="719"))*Balance!I$7:I$400) -> 0 | J16: =-SUMPRODUCT(((LEFT(Balance!$B$7:$B$400,3)="719"))*Balance!J$7:J$400) -> 0 | K16: =-SUMPRODUCT(((LEFT(Balance!$B$7:$B$400,3)="719"))*Balance!K$7:K$400) -> 0 | ... P16: =-SUMPRODUCT(((LEFT(Balance!$B$7:$B$400,3)="719"))*Balance!P$7:P$400) -> 0 | Q16: =SUM(E16:P16) -> 300000
B17: TOTAL I | D17: =D11+D12+D13+D14+D15+D16 -> 11641667 | E17: =E11+E12+E13+E14+E15+E16 -> 10941667 | F17: =F11+F12+F13+F14+F15+F16 -> 11441667 | G17: =G11+G12+G13+G14+G15+G16 -> 12791667 | H17: =H11+H12+H13+H14+H15+H16 -> 12041667 | I17: =I11+I12+I13+I14+I15+I16 -> 12841667 | J17: =J11+J12+J13+J14+J15+J16 -> 13191667 | K17: =K11+K12+K13+K14+K15+K16 -> 11941667 | ... P17: =P11+P12+P13+P14+P15+P16 -> 13991667 | Q17: =SUM(E17:P17) -> 1.445e+08
B18: II CHARGES D'EXPLOITATION
B19: Achats revendus de marchandises | C19: 611 | D19: =SUMPRODUCT(((LEFT(Balance!$B$7:$B$400,3)="611"))*Balance!D$7:D$400) -> 33756.48 | E19: =SUMPRODUCT(((LEFT(Balance!$B$7:$B$400,3)="611"))*Balance!E$7:E$400) -> 32185.14 | F19: =SUMPRODUCT(((LEFT(Balance!$B$7:$B$400,3)="611"))*Balance!F$7:F$400) -> 33236.86 | G19: =SUMPRODUCT(((LEFT(Balance!$B$7:$B$400,3)="611"))*Balance!G$7:G$400) -> 37072.63 | H19: =SUMPRODUCT(((LEFT(Balance!$B$7:$B$400,3)="611"))*Balance!H$7:H$400) -> 35194.96 | I19: =SUMPRODUCT(((LEFT(Balance!$B$7:$B$400,3)="611"))*Balance!I$7:I$400) -> 37313.05 | J19: =SUMPRODUCT(((LEFT(Balance!$B$7:$B$400,3)="611"))*Balance!J$7:J$400) -> 37801.13 | K19: =SUMPRODUCT(((LEFT(Balance!$B$7:$B$400,3)="611"))*Balance!K$7:K$400) -> 34094.72 | ... P19: =SUMPRODUCT(((LEFT(Balance!$B$7:$B$400,3)="611"))*Balance!P$7:P$400) -> 41759.13 | Q19: =SUM(E19:P19) -> 420000
B20: Achats consommés de matières et fournitures | C20: 612 | D20: =SUMPRODUCT(((LEFT(Balance!$B$7:$B$400,3)="612"))*Balance!D$7:D$400) -> 5025676.6 | E20: =SUMPRODUCT(((LEFT(Balance!$B$7:$B$400,3)="612"))*Balance!E$7:E$400) -> 4551601.7 | F20: =SUMPRODUCT(((LEFT(Balance!$B$7:$B$400,3)="612"))*Balance!F$7:F$400) -> 4610348.9 | G20: =SUMPRODUCT(((LEFT(Balance!$B$7:$B$400,3)="612"))*Balance!G$7:G$400) -> 5093312 | H20: =SUMPRODUCT(((LEFT(Balance!$B$7:$B$400,3)="612"))*Balance!H$7:H$400) -> 5438439 | I20: =SUMPRODUCT(((LEFT(Balance!$B$7:$B$400,3)="612"))*Balance!I$7:I$400) -> 5452504.5 | J20: =SUMPRODUCT(((LEFT(Balance!$B$7:$B$400,3)="612"))*Balance!J$7:J$400) -> 5473004.6 | K20: =SUMPRODUCT(((LEFT(Balance!$B$7:$B$400,3)="612"))*Balance!K$7:K$400) -> 4884054.7 | ... P20: =SUMPRODUCT(((LEFT(Balance!$B$7:$B$400,3)="612"))*Balance!P$7:P$400) -> 6274389.2 | Q20: =SUM(E20:P20) -> 62000000
B21: Autres charges externes | C21: 613 / 614 | D21: =SUMPRODUCT(((LEFT(Balance!$B$7:$B$400,3)="613")+(LEFT(Balance!$B$7:$B$400,3)="614"))*Balance!D$7:D$400) -> 1158379.1 | E21: =SUMPRODUCT(((LEFT(Balance!$B$7:$B$400,3)="613")+(LEFT(Balance!$B$7:$B$400,3)="614"))*Balance!E$7:E$400) -> 1146546 | F21: =SUMPRODUCT(((LEFT(Balance!$B$7:$B$400,3)="613")+(LEFT(Balance!$B$7:$B$400,3)="614"))*Balance!F$7:F$400) -> 1122853.7 | G21: =SUMPRODUCT(((LEFT(Balance!$B$7:$B$400,3)="613")+(LEFT(Balance!$B$7:$B$400,3)="614"))*Balance!G$7:G$400) -> 1209678.1 | H21: =SUMPRODUCT(((LEFT(Balance!$B$7:$B$400,3)="613")+(LEFT(Balance!$B$7:$B$400,3)="614"))*Balance!H$7:H$400) -> 1164908.9 | I21: =SUMPRODUCT(((LEFT(Balance!$B$7:$B$400,3)="613")+(LEFT(Balance!$B$7:$B$400,3)="614"))*Balance!I$7:I$400) -> 1197993.7 | J21: =SUMPRODUCT(((LEFT(Balance!$B$7:$B$400,3)="613")+(LEFT(Balance!$B$7:$B$400,3)="614"))*Balance!J$7:J$400) -> 1185017.4 | K21: =SUMPRODUCT(((LEFT(Balance!$B$7:$B$400,3)="613")+(LEFT(Balance!$B$7:$B$400,3)="614"))*Balance!K$7:K$400) -> 1169684.8 | ... P21: =SUMPRODUCT(((LEFT(Balance!$B$7:$B$400,3)="613")+(LEFT(Balance!$B$7:$B$400,3)="614"))*Balance!P$7:P$400) -> 1231499.8 | Q21: =SUM(E21:P21) -> 14000000
B22: Impôts et taxes | C22: 616 | D22: =SUMPRODUCT(((LEFT(Balance!$B$7:$B$400,3)="616"))*Balance!D$7:D$400) -> 127825.77 | E22: =SUMPRODUCT(((LEFT(Balance!$B$7:$B$400,3)="616"))*Balance!E$7:E$400) -> 124008.07 | F22: =SUMPRODUCT(((LEFT(Balance!$B$7:$B$400,3)="616"))*Balance!F$7:F$400) -> 122433.54 | G22: =SUMPRODUCT(((LEFT(Balance!$B$7:$B$400,3)="616"))*Balance!G$7:G$400) -> 121085.58 | H22: =SUMPRODUCT(((LEFT(Balance!$B$7:$B$400,3)="616"))*Balance!H$7:H$400) -> 126320.6 | I22: =SUMPRODUCT(((LEFT(Balance!$B$7:$B$400,3)="616"))*Balance!I$7:I$400) -> 130520.87 | J22: =SUMPRODUCT(((LEFT(Balance!$B$7:$B$400,3)="616"))*Balance!J$7:J$400) -> 121765.77 | K22: =SUMPRODUCT(((LEFT(Balance!$B$7:$B$400,3)="616"))*Balance!K$7:K$400) -> 126809.99 | ... P22: =SUMPRODUCT(((LEFT(Balance!$B$7:$B$400,3)="616"))*Balance!P$7:P$400) -> 124656.9 | Q22: =SUM(E22:P22) -> 1500000
B23: Charges de personnel | C23: 617 | D23: =SUMPRODUCT(((LEFT(Balance!$B$7:$B$400,3)="617"))*Balance!D$7:D$400) -> 3979693.9 | E23: =SUMPRODUCT(((LEFT(Balance!$B$7:$B$400,3)="617"))*Balance!E$7:E$400) -> 3242539.6 | F23: =SUMPRODUCT(((LEFT(Balance!$B$7:$B$400,3)="617"))*Balance!F$7:F$400) -> 3247018.7 | G23: =SUMPRODUCT(((LEFT(Balance!$B$7:$B$400,3)="617"))*Balance!G$7:G$400) -> 3298230 | H23: =SUMPRODUCT(((LEFT(Balance!$B$7:$B$400,3)="617"))*Balance!H$7:H$400) -> 3270907.5 | I23: =SUMPRODUCT(((LEFT(Balance!$B$7:$B$400,3)="617"))*Balance!I$7:I$400) -> 3300900.7 | J23: =SUMPRODUCT(((LEFT(Balance!$B$7:$B$400,3)="617"))*Balance!J$7:J$400) -> 3270750.3 | K23: =SUMPRODUCT(((LEFT(Balance!$B$7:$B$400,3)="617"))*Balance!K$7:K$400) -> 3275585.1 | ... P23: =SUMPRODUCT(((LEFT(Balance!$B$7:$B$400,3)="617"))*Balance!P$7:P$400) -> 4155077.2 | Q23: =SUM(E23:P23) -> 40000000
B24: Autres charges d'exploitation | C24: 618 | D24: =SUMPRODUCT(((LEFT(Balance!$B$7:$B$400,3)="618"))*Balance!D$7:D$400) -> 0 | E24: =SUMPRODUCT(((LEFT(Balance!$B$7:$B$400,3)="618"))*Balance!E$7:E$400) -> 0 | F24: =SUMPRODUCT(((LEFT(Balance!$B$7:$B$400,3)="618"))*Balance!F$7:F$400) -> 0 | G24: =SUMPRODUCT(((LEFT(Balance!$B$7:$B$400,3)="618"))*Balance!G$7:G$400) -> 0 | H24: =SUMPRODUCT(((LEFT(Balance!$B$7:$B$400,3)="618"))*Balance!H$7:H$400) -> 0 | I24: =SUMPRODUCT(((LEFT(Balance!$B$7:$B$400,3)="618"))*Balance!I$7:I$400) -> 0 | J24: =SUMPRODUCT(((LEFT(Balance!$B$7:$B$400,3)="618"))*Balance!J$7:J$400) -> 0 | K24: =SUMPRODUCT(((LEFT(Balance!$B$7:$B$400,3)="618"))*Balance!K$7:K$400) -> 0 | ... P24: =SUMPRODUCT(((LEFT(Balance!$B$7:$B$400,3)="618"))*Balance!P$7:P$400) -> 0 | Q24: =SUM(E24:P24) -> 100000
B25: Dotations d'exploitation | C25: 619 | D25: =SUMPRODUCT(((LEFT(Balance!$B$7:$B$400,3)="619"))*Balance!D$7:D$400) -> 813333.33 | E25: =SUMPRODUCT(((LEFT(Balance!$B$7:$B$400,3)="619"))*Balance!E$7:E$400) -> 733333.33 | F25: =SUMPRODUCT(((LEFT(Balance!$B$7:$B$400,3)="619"))*Balance!F$7:F$400) -> 733333.33 | G25: =SUMPRODUCT(((LEFT(Balance!$B$7:$B$400,3)="619"))*Balance!G$7:G$400) -> 733333.33 | H25: =SUMPRODUCT(((LEFT(Balance!$B$7:$B$400,3)="619"))*Balance!H$7:H$400) -> 733333.33 | I25: =SUMPRODUCT(((LEFT(Balance!$B$7:$B$400,3)="619"))*Balance!I$7:I$400) -> 733333.33 | J25: =SUMPRODUCT(((LEFT(Balance!$B$7:$B$400,3)="619"))*Balance!J$7:J$400) -> 833333.33 | K25: =SUMPRODUCT(((LEFT(Balance!$B$7:$B$400,3)="619"))*Balance!K$7:K$400) -> 733333.33 | ... P25: =SUMPRODUCT(((LEFT(Balance!$B$7:$B$400,3)="619"))*Balance!P$7:P$400) -> 833333.33 | Q25: =SUM(E25:P25) -> 9000000
B26: TOTAL II | D26: =D19+D20+D21+D22+D23+D24+D25 -> 11138665 | E26: =E19+E20+E21+E22+E23+E24+E25 -> 9830213.8 | F26: =F19+F20+F21+F22+F23+F24+F25 -> 9869225.1 | G26: =G19+G20+G21+G22+G23+G24+G25 -> 10492712 | H26: =H19+H20+H21+H22+H23+H24+H25 -> 10769104 | I26: =I19+I20+I21+I22+I23+I24+I25 -> 10852566 | J26: =J19+J20+J21+J22+J23+J24+J25 -> 10921672 | K26: =K19+K20+K21+K22+K23+K24+K25 -> 10223563 | ... P26: =P19+P20+P21+P22+P23+P24+P25 -> 12660715 | Q26: =SUM(E26:P26) -> 1.2702e+08
B27: III RÉSULTAT D'EXPLOITATION (I − II) | D27: =D17-D26 -> 503001.5 | E27: =E17-E26 -> 1111452.9 | F27: =F17-F26 -> 1572441.6 | G27: =G17-G26 -> 2298955.1 | H27: =H17-H26 -> 1272562.4 | I27: =I17-I26 -> 1989100.6 | J27: =J17-J26 -> 2269994.2 | K27: =K17-K26 -> 1718104.1 | ... P27: =P17-P26 -> 1330951.2 | Q27: =SUM(E27:P27) -> 17480000
B28: FINANCIER
B29: IV PRODUITS FINANCIERS
B30: Produits des titres de participation et autres titres immobilisés | C30: 732 | D30: =-SUMPRODUCT(((LEFT(Balance!$B$7:$B$400,3)="732"))*Balance!D$7:D$400) -> 0 | E30: =-SUMPRODUCT(((LEFT(Balance!$B$7:$B$400,3)="732"))*Balance!E$7:E$400) -> 0 | F30: =-SUMPRODUCT(((LEFT(Balance!$B$7:$B$400,3)="732"))*Balance!F$7:F$400) -> 0 | G30: =-SUMPRODUCT(((LEFT(Balance!$B$7:$B$400,3)="732"))*Balance!G$7:G$400) -> 0 | H30: =-SUMPRODUCT(((LEFT(Balance!$B$7:$B$400,3)="732"))*Balance!H$7:H$400) -> 0 | I30: =-SUMPRODUCT(((LEFT(Balance!$B$7:$B$400,3)="732"))*Balance!I$7:I$400) -> 0 | J30: =-SUMPRODUCT(((LEFT(Balance!$B$7:$B$400,3)="732"))*Balance!J$7:J$400) -> 0 | K30: =-SUMPRODUCT(((LEFT(Balance!$B$7:$B$400,3)="732"))*Balance!K$7:K$400) -> 0 | ... P30: =-SUMPRODUCT(((LEFT(Balance!$B$7:$B$400,3)="732"))*Balance!P$7:P$400) -> 0 | Q30: =SUM(E30:P30) -> 0
B31: Gains de change | C31: 733 | D31: =-SUMPRODUCT(((LEFT(Balance!$B$7:$B$400,3)="733"))*Balance!D$7:D$400) -> 120000 | E31: =-SUMPRODUCT(((LEFT(Balance!$B$7:$B$400,3)="733"))*Balance!E$7:E$400) -> 120000 | F31: =-SUMPRODUCT(((LEFT(Balance!$B$7:$B$400,3)="733"))*Balance!F$7:F$400) -> 100000 | G31: =-SUMPRODUCT(((LEFT(Balance!$B$7:$B$400,3)="733"))*Balance!G$7:G$400) -> 40000 | H31: =-SUMPRODUCT(((LEFT(Balance!$B$7:$B$400,3)="733"))*Balance!H$7:H$400) -> 150000 | I31: =-SUMPRODUCT(((LEFT(Balance!$B$7:$B$400,3)="733"))*Balance!I$7:I$400) -> 130000 | J31: =-SUMPRODUCT(((LEFT(Balance!$B$7:$B$400,3)="733"))*Balance!J$7:J$400) -> 140000 | K31: =-SUMPRODUCT(((LEFT(Balance!$B$7:$B$400,3)="733"))*Balance!K$7:K$400) -> 110000 | ... P31: =-SUMPRODUCT(((LEFT(Balance!$B$7:$B$400,3)="733"))*Balance!P$7:P$400) -> 140000 | Q31: =SUM(E31:P31) -> 1400000
B32: Intérêts et autres produits financiers | C32: 738 | D32: =-SUMPRODUCT(((LEFT(Balance!$B$7:$B$400,3)="738"))*Balance!D$7:D$400) -> 20595.43 | E32: =-SUMPRODUCT(((LEFT(Balance!$B$7:$B$400,3)="738"))*Balance!E$7:E$400) -> 19582.63 | F32: =-SUMPRODUCT(((LEFT(Balance!$B$7:$B$400,3)="738"))*Balance!F$7:F$400) -> 20053.32 | G32: =-SUMPRODUCT(((LEFT(Balance!$B$7:$B$400,3)="738"))*Balance!G$7:G$400) -> 21389.3 | H32: =-SUMPRODUCT(((LEFT(Balance!$B$7:$B$400,3)="738"))*Balance!H$7:H$400) -> 21125.16 | I32: =-SUMPRODUCT(((LEFT(Balance!$B$7:$B$400,3)="738"))*Balance!I$7:I$400) -> 21604.6 | J32: =-SUMPRODUCT(((LEFT(Balance!$B$7:$B$400,3)="738"))*Balance!J$7:J$400) -> 21886.58 | K32: =-SUMPRODUCT(((LEFT(Balance!$B$7:$B$400,3)="738"))*Balance!K$7:K$400) -> 20833.48 | ... P32: =-SUMPRODUCT(((LEFT(Balance!$B$7:$B$400,3)="738"))*Balance!P$7:P$400) -> 23189.36 | Q32: =SUM(E32:P32) -> 249999.97
B33: Reprises financières ; transferts de charges | C33: 739 | D33: =-SUMPRODUCT(((LEFT(Balance!$B$7:$B$400,3)="739"))*Balance!D$7:D$400) -> 0 | E33: =-SUMPRODUCT(((LEFT(Balance!$B$7:$B$400,3)="739"))*Balance!E$7:E$400) -> 0 | F33: =-SUMPRODUCT(((LEFT(Balance!$B$7:$B$400,3)="739"))*Balance!F$7:F$400) -> 0 | G33: =-SUMPRODUCT(((LEFT(Balance!$B$7:$B$400,3)="739"))*Balance!G$7:G$400) -> 0 | H33: =-SUMPRODUCT(((LEFT(Balance!$B$7:$B$400,3)="739"))*Balance!H$7:H$400) -> 0 | I33: =-SUMPRODUCT(((LEFT(Balance!$B$7:$B$400,3)="739"))*Balance!I$7:I$400) -> 0 | J33: =-SUMPRODUCT(((LEFT(Balance!$B$7:$B$400,3)="739"))*Balance!J$7:J$400) -> 0 | K33: =-SUMPRODUCT(((LEFT(Balance!$B$7:$B$400,3)="739"))*Balance!K$7:K$400) -> 0 | ... P33: =-SUMPRODUCT(((LEFT(Balance!$B$7:$B$400,3)="739"))*Balance!P$7:P$400) -> 0 | Q33: =SUM(E33:P33) -> 0
B34: TOTAL IV | D34: =D30+D31+D32+D33 -> 140595.43 | E34: =E30+E31+E32+E33 -> 139582.63 | F34: =F30+F31+F32+F33 -> 120053.32 | G34: =G30+G31+G32+G33 -> 61389.3 | H34: =H30+H31+H32+H33 -> 171125.16 | I34: =I30+I31+I32+I33 -> 151604.6 | J34: =J30+J31+J32+J33 -> 161886.58 | K34: =K30+K31+K32+K33 -> 130833.48 | ... P34: =P30+P31+P32+P33 -> 163189.36 | Q34: =SUM(E34:P34) -> 1650000
B35: V CHARGES FINANCIÈRES
B36: Charges d'intérêts | C36: 631 | D36: =SUMPRODUCT(((LEFT(Balance!$B$7:$B$400,3)="631"))*Balance!D$7:D$400) -> 282826.99 | E36: =SUMPRODUCT(((LEFT(Balance!$B$7:$B$400,3)="631"))*Balance!E$7:E$400) -> 280012.79 | F36: =SUMPRODUCT(((LEFT(Balance!$B$7:$B$400,3)="631"))*Balance!F$7:F$400) -> 277198.59 | G36: =SUMPRODUCT(((LEFT(Balance!$B$7:$B$400,3)="631"))*Balance!G$7:G$400) -> 274384.39 | H36: =SUMPRODUCT(((LEFT(Balance!$B$7:$B$400,3)="631"))*Balance!H$7:H$400) -> 271570.2 | I36: =SUMPRODUCT(((LEFT(Balance!$B$7:$B$400,3)="631"))*Balance!I$7:I$400) -> 268756 | J36: =SUMPRODUCT(((LEFT(Balance!$B$7:$B$400,3)="631"))*Balance!J$7:J$400) -> 265941.8 | K36: =SUMPRODUCT(((LEFT(Balance!$B$7:$B$400,3)="631"))*Balance!K$7:K$400) -> 265685.96 | ... P36: =SUMPRODUCT(((LEFT(Balance!$B$7:$B$400,3)="631"))*Balance!P$7:P$400) -> 249056.6 | Q36: =SUM(E36:P36) -> 3200000
B37: Pertes de change | C37: 633 | D37: =SUMPRODUCT(((LEFT(Balance!$B$7:$B$400,3)="633"))*Balance!D$7:D$400) -> 100000 | E37: =SUMPRODUCT(((LEFT(Balance!$B$7:$B$400,3)="633"))*Balance!E$7:E$400) -> 50000 | F37: =SUMPRODUCT(((LEFT(Balance!$B$7:$B$400,3)="633"))*Balance!F$7:F$400) -> 80000 | G37: =SUMPRODUCT(((LEFT(Balance!$B$7:$B$400,3)="633"))*Balance!G$7:G$400) -> 750000 | H37: =SUMPRODUCT(((LEFT(Balance!$B$7:$B$400,3)="633"))*Balance!H$7:H$400) -> 100000 | I37: =SUMPRODUCT(((LEFT(Balance!$B$7:$B$400,3)="633"))*Balance!I$7:I$400) -> 80000 | J37: =SUMPRODUCT(((LEFT(Balance!$B$7:$B$400,3)="633"))*Balance!J$7:J$400) -> 60000 | K37: =SUMPRODUCT(((LEFT(Balance!$B$7:$B$400,3)="633"))*Balance!K$7:K$400) -> 100000 | ... P37: =SUMPRODUCT(((LEFT(Balance!$B$7:$B$400,3)="633"))*Balance!P$7:P$400) -> 70000 | Q37: =SUM(E37:P37) -> 1800000
B38: Autres charges financières | C38: 638 | D38: =SUMPRODUCT(((LEFT(Balance!$B$7:$B$400,3)="638"))*Balance!D$7:D$400) -> 12220.52 | E38: =SUMPRODUCT(((LEFT(Balance!$B$7:$B$400,3)="638"))*Balance!E$7:E$400) -> 11434.78 | F38: =SUMPRODUCT(((LEFT(Balance!$B$7:$B$400,3)="638"))*Balance!F$7:F$400) -> 11936.62 | G38: =SUMPRODUCT(((LEFT(Balance!$B$7:$B$400,3)="638"))*Balance!G$7:G$400) -> 13294 | H38: =SUMPRODUCT(((LEFT(Balance!$B$7:$B$400,3)="638"))*Balance!H$7:H$400) -> 12619.19 | I38: =SUMPRODUCT(((LEFT(Balance!$B$7:$B$400,3)="638"))*Balance!I$7:I$400) -> 13246.78 | J38: =SUMPRODUCT(((LEFT(Balance!$B$7:$B$400,3)="638"))*Balance!J$7:J$400) -> 13584.99 | K38: =SUMPRODUCT(((LEFT(Balance!$B$7:$B$400,3)="638"))*Balance!K$7:K$400) -> 12223.61 | ... P38: =SUMPRODUCT(((LEFT(Balance!$B$7:$B$400,3)="638"))*Balance!P$7:P$400) -> 14569.51 | Q38: =SUM(E38:P38) -> 150000
B39: Dotations financières | C39: 639 | D39: =SUMPRODUCT(((LEFT(Balance!$B$7:$B$400,3)="639"))*Balance!D$7:D$400) -> 0 | E39: =SUMPRODUCT(((LEFT(Balance!$B$7:$B$400,3)="639"))*Balance!E$7:E$400) -> 0 | F39: =SUMPRODUCT(((LEFT(Balance!$B$7:$B$400,3)="639"))*Balance!F$7:F$400) -> 0 | G39: =SUMPRODUCT(((LEFT(Balance!$B$7:$B$400,3)="639"))*Balance!G$7:G$400) -> 0 | H39: =SUMPRODUCT(((LEFT(Balance!$B$7:$B$400,3)="639"))*Balance!H$7:H$400) -> 0 | I39: =SUMPRODUCT(((LEFT(Balance!$B$7:$B$400,3)="639"))*Balance!I$7:I$400) -> 0 | J39: =SUMPRODUCT(((LEFT(Balance!$B$7:$B$400,3)="639"))*Balance!J$7:J$400) -> 0 | K39: =SUMPRODUCT(((LEFT(Balance!$B$7:$B$400,3)="639"))*Balance!K$7:K$400) -> 0 | ... P39: =SUMPRODUCT(((LEFT(Balance!$B$7:$B$400,3)="639"))*Balance!P$7:P$400) -> 0 | Q39: =SUM(E39:P39) -> 0
B40: TOTAL V | D40: =D36+D37+D38+D39 -> 395047.51 | E40: =E36+E37+E38+E39 -> 341447.57 | F40: =F36+F37+F38+F39 -> 369135.21 | G40: =G36+G37+G38+G39 -> 1037678.4 | H40: =H36+H37+H38+H39 -> 384189.39 | I40: =I36+I37+I38+I39 -> 362002.78 | J40: =J36+J37+J38+J39 -> 339526.79 | K40: =K36+K37+K38+K39 -> 377909.57 | ... P40: =P36+P37+P38+P39 -> 333626.11 | Q40: =SUM(E40:P40) -> 5150000
B41: VI RÉSULTAT FINANCIER (IV − V) | D41: =D34-D40 -> -254452.08 | E41: =E34-E40 -> -201864.94 | F41: =F34-F40 -> -249081.89 | G41: =G34-G40 -> -976289.09 | H41: =H34-H40 -> -213064.23 | I41: =I34-I40 -> -210398.18 | J41: =J34-J40 -> -177640.21 | K41: =K34-K40 -> -247076.09 | ... P41: =P34-P40 -> -170436.75 | Q41: =SUM(E41:P41) -> -3500000
B42: VII RÉSULTAT COURANT (III + VI) | D42: =D27+D41 -> 248549.42 | E42: =E27+E41 -> 909587.95 | F42: =F27+F41 -> 1323359.7 | G42: =G27+G41 -> 1322666 | H42: =H27+H41 -> 1059498.2 | I42: =I27+I41 -> 1778702.4 | J42: =J27+J41 -> 2092354 | K42: =K27+K41 -> 1471028 | ... P42: =P27+P41 -> 1160514.4 | Q42: =SUM(E42:P42) -> 13980000
...

Sheet ESG
B1: ÉTAT DES SOLDES DE GESTION (ESG) — MODÈLE CGNC
B2: ="Société : "&Accueil!$C$8&" │ Exercice : "&Accueil!$C$11&" │ Date d'arrêté : "&Accueil!$C$12&" │ Responsable : "&Accueil!$C$15 -> Société : AéroAtlas Composites SARL │ Exercice : 2025 │ Date d'arrêté : 31/12/2025 │ Responsable : Karim El Fassi (DAF)
B4: ← Accueil | C4: I. Tableau de formation des résultats (TFR) │ II. Capacité d'autofinancement (CAF) — Autofinancement │ Liens : CPC + Balance
B6: Soldes de gestion | C6: Réf. | D6: Déc. N-1 | E6: Janvier | F6: Février | G6: Mars | H6: Avril | I6: Mai | J6: Juin | K6: Juillet | L6: Août | M6: Septembre | N6: Octobre | O6: Novembre | P6: Décembre | Q6: TOTAL 2025
B7: I. TABLEAU DE FORMATION DES RÉSULTATS (TFR)
B8: 1 Ventes de marchandises (en l'état) | C8: CPC | D8: =CPC!D9 -> 48759.93 | E8: =CPC!E9 -> 46033.13 | F8: =CPC!F9 -> 47260.36 | G8: =CPC!G9 -> 51367.28 | H8: =CPC!H9 -> 48774.59 | I8: =CPC!I9 -> 54751.3 | J8: =CPC!J9 -> 54310.72 | K8: =CPC!K9 -> 47737.13 | ... P8: =CPC!P9 -> 58145.28 | Q8: =SUM(E8:P8) -> 597614.05
B9: 2 − Achats revendus de marchandises | C9: CPC | D9: =CPC!D19 -> 33756.48 | E9: =CPC!E19 -> 32185.14 | F9: =CPC!F19 -> 33236.86 | G9: =CPC!G19 -> 37072.63 | H9: =CPC!H19 -> 35194.96 | I9: =CPC!I19 -> 37313.05 | J9: =CPC!J19 -> 37801.13 | K9: =CPC!K19 -> 34094.72 | ... P9: =CPC!P19 -> 41759.13 | Q9: =SUM(E9:P9) -> 420000
B10: I = MARGE BRUTE SUR VENTES EN L'ÉTAT | D10: =D8-D9 -> 15003.45 | E10: =E8-E9 -> 13847.99 | F10: =F8-F9 -> 14023.5 | G10: =G8-G9 -> 14294.65 | H10: =H8-H9 -> 13579.63 | I10: =I8-I9 -> 17438.25 | J10: =J8-J9 -> 16509.59 | K10: =K8-K9 -> 13642.41 | ... P10: =P8-P9 -> 16386.15 | Q10: =SUM(E10:P10) -> 177614.05
B11: 3 Ventes de biens et services produits | C11: CPC | D11: =CPC!D10 -> 11451240 | E11: =CPC!E10 -> 10753967 | F11: =CPC!F10 -> 11152740 | G11: =CPC!G10 -> 12348633 | H11: =CPC!H10 -> 11851225 | I11: =CPC!I10 -> 12545249 | J11: =CPC!J10 -> 12745689 | K11: =CPC!K10 -> 11552263 | ... P11: =CPC!P10 -> 14041855 | Q11: =SUM(E11:P11) -> 1.4140239e+08
B12: 4 Variation de stocks de produits | C12: CPC | D12: =CPC!D12 -> 100000 | E12: =CPC!E12 -> 100000 | F12: =CPC!F12 -> 200000 | G12: =CPC!G12 -> 200000 | H12: =CPC!H12 -> 100000 | I12: =CPC!I12 -> 200000 | J12: =CPC!J12 -> 100000 | K12: =CPC!K12 -> 300000 | ... P12: =CPC!P12 -> -400000 | Q12: =SUM(E12:P12) -> 1200000
B13: 5 Immobilisations produites par l'entreprise pour elle-même | C13: CPC | D13: =CPC!D13 -> 0 | E13: =CPC!E13 -> 0 | F13: =CPC!F13 -> 0 | G13: =CPC!G13 -> 0 | H13: =CPC!H13 -> 0 | I13: =CPC!I13 -> 0 | J13: =CPC!J13 -> 0 | K13: =CPC!K13 -> 0 | ... P13: =CPC!P13 -> 0 | Q13: =SUM(E13:P13) -> 0
B14: II + PRODUCTION DE L'EXERCICE (3 + 4 + 5) | D14: =D11+D12+D13 -> 11551240 | E14: =E11+E12+E13 -> 10853967 | F14: =F11+F12+F13 -> 11352740 | G14: =G11+G12+G13 -> 12548633 | H14: =H11+H12+H13 -> 11951225 | I14: =I11+I12+I13 -> 12745249 | J14: =J11+J12+J13 -> 12845689 | K14: =K11+K12+K13 -> 11852263 | ... P14: =P11+P12+P13 -> 13641855 | Q14: =SUM(E14:P14) -> 1.4260239e+08
B15: 6 Achats consommés de matières et fournitures | C15: CPC | D15: =CPC!D20 -> 5025676.6 | E15: =CPC!E20 -> 4551601.7 | F15: =CPC!F20 -> 4610348.9 | G15: =CPC!G20 -> 5093312 | H15: =CPC!H20 -> 5438439 | I15: =CPC!I20 -> 5452504.5 | J15: =CPC!J20 -> 5473004.6 | K15: =CPC!K20 -> 4884054.7 | ... P15: =CPC!P20 -> 6274389.2 | Q15: =SUM(E15:P15) -> 62000000
B16: 7 Autres charges externes | C16: CPC | D16: =CPC!D21 -> 1158379.1 | E16: =CPC!E21 -> 1146546 | F16: =CPC!F21 -> 1122853.7 | G16: =CPC!G21 -> 1209678.1 | H16: =CPC!H21 -> 1164908.9 | I16: =CPC!I21 -> 1197993.7 | J16: =CPC!J21 -> 1185017.4 | K16: =CPC!K21 -> 1169684.8 | ... P16: =CPC!P21 -> 1231499.8 | Q16: =SUM(E16:P16) -> 14000000
B17: III − CONSOMMATION DE L'EXERCICE (6 + 7) | D17: =D15+D16 -> 6184055.7 | E17: =E15+E16 -> 5698147.7 | F17: =F15+F16 -> 5733202.6 | G17: =G15+G16 -> 6302990.1 | H17: =H15+H16 -> 6603347.8 | I17: =I15+I16 -> 6650498.1 | J17: =J15+J16 -> 6658021.9 | K17: =K15+K16 -> 6053739.5 | ... P17: =P15+P16 -> 7505888.9 | Q17: =SUM(E17:P17) -> 76000000
B18: IV = VALEUR AJOUTÉE (I + II − III) | D18: =D10+D14-D17 -> 5382187.8 | E18: =E10+E14-E17 -> 5169667.2 | F18: =F10+F14-F17 -> 5633560.5 | G18: =G10+G14-G17 -> 6259937.3 | H18: =H10+H14-H17 -> 5361457.2 | I18: =I10+I14-I17 -> 6112188.8 | J18: =J10+J14-J17 -> 6204176.9 | K18: =K10+K14-K17 -> 5812165.8 | ... P18: =P10+P14-P17 -> 6152352 | Q18: =SUM(E18:P18) -> 66780000
B19: 8 + Subventions d'exploitation | C19: CPC | D19: =CPC!D14 -> 0 | E19: =CPC!E14 -> 0 | F19: =CPC!F14 -> 0 | G19: =CPC!G14 -> 0 | H19: =CPC!H14 -> 0 | I19: =CPC!I14 -> 0 | J19: =CPC!J14 -> 250000 | K19: =CPC!K14 -> 0 | ... P19: =CPC!P14 -> 250000 | Q19: =SUM(E19:P19) -> 500000
B20: 9 − Impôts et taxes | C20: CPC | D20: =CPC!D22 -> 127825.77 | E20: =CPC!E22 -> 124008.07 | F20: =CPC!F22 -> 122433.54 | G20: =CPC!G22 -> 121085.58 | H20: =CPC!H22 -> 126320.6 | I20: =CPC!I22 -> 130520.87 | J20: =CPC!J22 -> 121765.77 | K20: =CPC!K22 -> 126809.99 | ... P20: =CPC!P22 -> 124656.9 | Q20: =SUM(E20:P20) -> 1500000
B21: 10 − Charges de personnel | C21: CPC | D21: =CPC!D23 -> 3979693.9 | E21: =CPC!E23 -> 3242539.6 | F21: =CPC!F23 -> 3247018.7 | G21: =CPC!G23 -> 3298230 | H21: =CPC!H23 -> 3270907.5 | I21: =CPC!I23 -> 3300900.7 | J21: =CPC!J23 -> 3270750.3 | K21: =CPC!K23 -> 3275585.1 | ... P21: =CPC!P23 -> 4155077.2 | Q21: =SUM(E21:P21) -> 40000000
B22: V = EXCÉDENT BRUT D'EXPLOITATION (EBE) ou INSUFFISANCE (IBE) | D22: =D18+D19-D20-D21 -> 1274668.2 | E22: =E18+E19-E20-E21 -> 1803119.6 | F22: =F18+F19-F20-F21 -> 2264108.3 | G22: =G18+G19-G20-G21 -> 2840621.7 | H22: =H18+H19-H20-H21 -> 1964229.1 | I22: =I18+I19-I20-I21 -> 2680767.3 | J22: =J18+J19-J20-J21 -> 3061660.9 | K22: =K18+K19-K20-K21 -> 2409770.7 | ... P22: =P18+P19-P20-P21 -> 2122617.9 | Q22: =SUM(E22:P22) -> 25780000
B23: 11 + Autres produits d'exploitation | C23: CPC | D23: =CPC!D15 -> 41666.67 | E23: =CPC!E15 -> 41666.67 | F23: =CPC!F15 -> 41666.67 | G23: =CPC!G15 -> 41666.67 | H23: =CPC!H15 -> 41666.67 | I23: =CPC!I15 -> 41666.67 | J23: =CPC!J15 -> 41666.67 | K23: =CPC!K15 -> 41666.67 | ... P23: =CPC!P15 -> 41666.67 | Q23: =SUM(E23:P23) -> 500000.04
B24: 12 − Autres charges d'exploitation | C24: CPC | D24: =CPC!D24 -> 0 | E24: =CPC!E24 -> 0 | F24: =CPC!F24 -> 0 | G24: =CPC!G24 -> 0 | H24: =CPC!H24 -> 0 | I24: =CPC!I24 -> 0 | J24: =CPC!J24 -> 0 | K24: =CPC!K24 -> 0 | ... P24: =CPC!P24 -> 0 | Q24: =SUM(E24:P24) -> 100000
B25: 13 + Reprises d'exploitation, transferts de charges | C25: CPC | D25: =CPC!D16 -> 0 | E25: =CPC!E16 -> 0 | F25: =CPC!F16 -> 0 | G25: =CPC!G16 -> 150000 | H25: =CPC!H16 -> 0 | I25: =CPC!I16 -> 0 | J25: =CPC!J16 -> 0 | K25: =CPC!K16 -> 0 | ... P25: =CPC!P16 -> 0 | Q25: =SUM(E25:P25) -> 300000
B26: 14 − Dotations d'exploitation | C26: CPC | D26: =CPC!D25 -> 813333.33 | E26: =CPC!E25 -> 733333.33 | F26: =CPC!F25 -> 733333.33 | G26: =CPC!G25 -> 733333.33 | H26: =CPC!H25 -> 733333.33 | I26: =CPC!I25 -> 733333.33 | J26: =CPC!J25 -> 833333.33 | K26: =CPC!K25 -> 733333.33 | ... P26: =CPC!P25 -> 833333.33 | Q26: =SUM(E26:P26) -> 9000000
B27: VI = RÉSULTAT D'EXPLOITATION (+ ou −) | D27: =D22+D23-D24+D25-D26 -> 503001.5 | E27: =E22+E23-E24+E25-E26 -> 1111452.9 | F27: =F22+F23-F24+F25-F26 -> 1572441.6 | G27: =G22+G23-G24+G25-G26 -> 2298955.1 | H27: =H22+H23-H24+H25-H26 -> 1272562.4 | I27: =I22+I23-I24+I25-I26 -> 1989100.6 | J27: =J22+J23-J24+J25-J26 -> 2269994.2 | K27: =K22+K23-K24+K25-K26 -> 1718104.1 | ... P27: =P22+P23-P24+P25-P26 -> 1330951.2 | Q27: =SUM(E27:P27) -> 17480000
B28: VII ± RÉSULTAT FINANCIER | C28: CPC | D28: =CPC!D41 -> -254452.08 | E28: =CPC!E41 -> -201864.94 | F28: =CPC!F41 -> -249081.89 | G28: =CPC!G41 -> -976289.09 | H28: =CPC!H41 -> -213064.23 | I28: =CPC!I41 -> -210398.18 | J28: =CPC!J41 -> -177640.21 | K28: =CPC!K41 -> -247076.09 | ... P28: =CPC!P41 -> -170436.75 | Q28: =SUM(E28:P28) -> -3500000
B29: VIII = RÉSULTAT COURANT (+ ou −) | D29: =D27+D28 -> 248549.42 | E29: =E27+E28 -> 909587.95 | F29: =F27+F28 -> 1323359.7 | G29: =G27+G28 -> 1322666 | H29: =H27+H28 -> 1059498.2 | I29: =I27+I28 -> 1778702.4 | J29: =J27+J28 -> 2092354 | K29: =K27+K28 -> 1471028 | ... P29: =P27+P28 -> 1160514.4 | Q29: =SUM(E29:P29) -> 13980000
B30: IX ± RÉSULTAT NON COURANT | C30: CPC | D30: =CPC!D57 -> 10000 | E30: =CPC!E57 -> 10000 | F30: =CPC!F57 -> 10000 | G30: =CPC!G57 -> 10000 | H30: =CPC!H57 -> 10000 | I30: =CPC!I57 -> 10000 | J30: =CPC!J57 -> 10000 | K30: =CPC!K57 -> 10000 | ... P30: =CPC!P57 -> 10000 | Q30: =SUM(E30:P30) -> -280000
B31: 15 − Impôts sur les résultats | C31: CPC | D31: =CPC!D59 -> 51709.88 | E31: =CPC!E59 -> 183917.58 | F31: =CPC!F59 -> 266671.94 | G31: =CPC!G59 -> 266533.19 | H31: =CPC!H59 -> 213899.64 | I31: =CPC!I59 -> 357740.48 | J31: =CPC!J59 -> 420470.8 | K31: =CPC!K59 -> 296205.59 | ... P31: =CPC!P59 -> 234102.89 | Q31: =SUM(E31:P31) -> 2740000
B32: X = RÉSULTAT NET DE L'EXERCICE | D32: =D29+D30-D31 -> 206839.54 | E32: =E29+E30-E31 -> 735670.37 | F32: =F29+F30-F31 -> 1066687.8 | G32: =G29+G30-G31 -> 1066132.8 | H32: =H29+H30-H31 -> 855598.55 | I32: =I29+I30-I31 -> 1430961.9 | J32: =J29+J30-J31 -> 1681883.2 | K32: =K29+K30-K31 -> 1184822.4 | ... P32: =P29+P30-P31 -> 936411.55 | Q32: =SUM(E32:P32) -> 10960000
B33: II. CAPACITÉ D'AUTOFINANCEMENT (CAF) — AUTOFINANCEMENT
B34: 1 Résultat net de l'exercice | C34: ESG X | D34: =D32 -> 206839.54 | E34: =E32 -> 735670.37 | F34: =F32 -> 1066687.8 | G34: =G32 -> 1066132.8 | H34: =H32 -> 855598.55 | I34: =I32 -> 1430961.9 | J34: =J32 -> 1681883.2 | K34: =K32 -> 1184822.4 | ... P34: =P32 -> 936411.55 | Q34: =SUM(E34:P34) -> 10960000
B35: 2 + Dotations d'exploitation (1) | C35: 6191-6195 | D35: =SUMPRODUCT(((LEFT(Balance!$B$7:$B$400,4)="6191")+(LEFT(Balance!$B$7:$B$400,4)="6192")+(LEFT(Balance!$B$7:$B$400,4)="6193")+(LEFT(Balance!$B$7:$B$400,4)="6194")+(LEFT(Balance!$B$7:$B$400,4)="6195"))*Balance!D$7:D$400) -> 733333.33 | E35: =SUMPRODUCT(((LEFT(Balance!$B$7:$B$400,4)="6191")+(LEFT(Balance!$B$7:$B$400,4)="6192")+(LEFT(Balance!$B$7:$B$400,4)="6193")+(LEFT(Balance!$B$7:$B$400,4)="6194")+(LEFT(Balance!$B$7:$B$400,4)="6195"))*Balance!E$7:E$400) -> 733333.33 | F35: =SUMPRODUCT(((LEFT(Balance!$B$7:$B$400,4)="6191")+(LEFT(Balance!$B$7:$B$400,4)="6192")+(LEFT(Balance!$B$7:$B$400,4)="6193")+(LEFT(Balance!$B$7:$B$400,4)="6194")+(LEFT(Balance!$B$7:$B$400,4)="6195"))*Balance!F$7:F$400) -> 733333.33 | G35: =SUMPRODUCT(((LEFT(Balance!$B$7:$B$400,4)="6191")+(LEFT(Balance!$B$7:$B$400,4)="6192")+(LEFT(Balance!$B$7:$B$400,4)="6193")+(LEFT(Balance!$B$7:$B$400,4)="6194")+(LEFT(Balance!$B$7:$B$400,4)="6195"))*Balance!G$7:G$400) -> 733333.33 | H35: =SUMPRODUCT(((LEFT(Balance!$B$7:$B$400,4)="6191")+(LEFT(Balance!$B$7:$B$400,4)="6192")+(LEFT(Balance!$B$7:$B$400,4)="6193")+(LEFT(Balance!$B$7:$B$400,4)="6194")+(LEFT(Balance!$B$7:$B$400,4)="6195"))*Balance!H$7:H$400) -> 733333.33 | I35: =SUMPRODUCT(((LEFT(Balance!$B$7:$B$400,4)="6191")+(LEFT(Balance!$B$7:$B$400,4)="6192")+(LEFT(Balance!$B$7:$B$400,4)="6193")+(LEFT(Balance!$B$7:$B$400,4)="6194")+(LEFT(Balance!$B$7:$B$400,4)="6195"))*Balance!I$7:I$400) -> 733333.33 | J35: =SUMPRODUCT(((LEFT(Balance!$B$7:$B$400,4)="6191")+(LEFT(Balance!$B$7:$B$400,4)="6192")+(LEFT(Balance!$B$7:$B$400,4)="6193")+(LEFT(Balance!$B$7:$B$400,4)="6194")+(LEFT(Balance!$B$7:$B$400,4)="6195"))*Balance!J$7:J$400) -> 733333.33 | K35: =SUMPRODUCT(((LEFT(Balance!$B$7:$B$400,4)="6191")+(LEFT(Balance!$B$7:$B$400,4)="6192")+(LEFT(Balance!$B$7:$B$400,4)="6193")+(LEFT(Balance!$B$7:$B$400,4)="6194")+(LEFT(Balance!$B$7:$B$400,4)="6195"))*Balance!K$7:K$400) -> 733333.33 | ... P35: =SUMPRODUCT(((LEFT(Balance!$B$7:$B$400,4)="6191")+(LEFT(Balance!$B$7:$B$400,4)="6192")+(LEFT(Balance!$B$7:$B$400,4)="6193")+(LEFT(Balance!$B$7:$B$400,4)="6194")+(LEFT(Balance!$B$7:$B$400,4)="6195"))*Balance!P$7:P$400) -> 733333.33 | Q35: =SUM(E35:P35) -> 8800000
B36: 3 + Dotations financières (1) | C36: 6392-6393 | D36: =SUMPRODUCT(((LEFT(Balance!$B$7:$B$400,4)="6392")+(LEFT(Balance!$B$7:$B$400,4)="6393"))*Balance!D$7:D$400) -> 0 | E36: =SUMPRODUCT(((LEFT(Balance!$B$7:$B$400,4)="6392")+(LEFT(Balance!$B$7:$B$400,4)="6393"))*Balance!E$7:E$400) -> 0 | F36: =SUMPRODUCT(((LEFT(Balance!$B$7:$B$400,4)="6392")+(LEFT(Balance!$B$7:$B$400,4)="6393"))*Balance!F$7:F$400) -> 0 | G36: =SUMPRODUCT(((LEFT(Balance!$B$7:$B$400,4)="6392")+(LEFT(Balance!$B$7:$B$400,4)="6393"))*Balance!G$7:G$400) -> 0 | H36: =SUMPRODUCT(((LEFT(Balance!$B$7:$B$400,4)="6392")+(LEFT(Balance!$B$7:$B$400,4)="6393"))*Balance!H$7:H$400) -> 0 | I36: =SUMPRODUCT(((LEFT(Balance!$B$7:$B$400,4)="6392")+(LEFT(Balance!$B$7:$B$400,4)="6393"))*Balance!I$7:I$400) -> 0 | J36: =SUMPRODUCT(((LEFT(Balance!$B$7:$B$400,4)="6392")+(LEFT(Balance!$B$7:$B$400,4)="6393"))*Balance!J$7:J$400) -> 0 | K36: =SUMPRODUCT(((LEFT(Balance!$B$7:$B$400,4)="6392")+(LEFT(Balance!$B$7:$B$400,4)="6393"))*Balance!K$7:K$400) -> 0 | ... P36: =SUMPRODUCT(((LEFT(Balance!$B$7:$B$400,4)="6392")+(LEFT(Balance!$B$7:$B$400,4)="6393"))*Balance!P$7:P$400) -> 0 | Q36: =SUM(E36:P36) -> 0
B37: 4 + Dotations non courantes (1) | C37: 6591-6595 | D37: =SUMPRODUCT(((LEFT(Balance!$B$7:$B$400,4)="6591")+(LEFT(Balance!$B$7:$B$400,4)="6592")+(LEFT(Balance!$B$7:$B$400,4)="6593")+(LEFT(Balance!$B$7:$B$400,4)="6594")+(LEFT(Balance!$B$7:$B$400,4)="6595"))*Balance!D$7:D$400) -> 0 | E37: =SUMPRODUCT(((LEFT(Balance!$B$7:$B$400,4)="6591")+(LEFT(Balance!$B$7:$B$400,4)="6592")+(LEFT(Balance!$B$7:$B$400,4)="6593")+(LEFT(Balance!$B$7:$B$400,4)="6594")+(LEFT(Balance!$B$7:$B$400,4)="6595"))*Balance!E$7:E$400) -> 0 | F37: =SUMPRODUCT(((LEFT(Balance!$B$7:$B$400,4)="6591")+(LEFT(Balance!$B$7:$B$400,4)="6592")+(LEFT(Balance!$B$7:$B$400,4)="6593")+(LEFT(Balance!$B$7:$B$400,4)="6594")+(LEFT(Balance!$B$7:$B$400,4)="6595"))*Balance!F$7:F$400) -> 0 | G37: =SUMPRODUCT(((LEFT(Balance!$B$7:$B$400,4)="6591")+(LEFT(Balance!$B$7:$B$400,4)="6592")+(LEFT(Balance!$B$7:$B$400,4)="6593")+(LEFT(Balance!$B$7:$B$400,4)="6594")+(LEFT(Balance!$B$7:$B$400,4)="6595"))*Balance!G$7:G$400) -> 0 | H37: =SUMPRODUCT(((LEFT(Balance!$B$7:$B$400,4)="6591")+(LEFT(Balance!$B$7:$B$400,4)="6592")+(LEFT(Balance!$B$7:$B$400,4)="6593")+(LEFT(Balance!$B$7:$B$400,4)="6594")+(LEFT(Balance!$B$7:$B$400,4)="6595"))*Balance!H$7:H$400) -> 0 | I37: =SUMPRODUCT(((LEFT(Balance!$B$7:$B$400,4)="6591")+(LEFT(Balance!$B$7:$B$400,4)="6592")+(LEFT(Balance!$B$7:$B$400,4)="6593")+(LEFT(Balance!$B$7:$B$400,4)="6594")+(LEFT(Balance!$B$7:$B$400,4)="6595"))*Balance!I$7:I$400) -> 0 | J37: =SUMPRODUCT(((LEFT(Balance!$B$7:$B$400,4)="6591")+(LEFT(Balance!$B$7:$B$400,4)="6592")+(LEFT(Balance!$B$7:$B$400,4)="6593")+(LEFT(Balance!$B$7:$B$400,4)="6594")+(LEFT(Balance!$B$7:$B$400,4)="6595"))*Balance!J$7:J$400) -> 0 | K37: =SUMPRODUCT(((LEFT(Balance!$B$7:$B$400,4)="6591")+(LEFT(Balance!$B$7:$B$400,4)="6592")+(LEFT(Balance!$B$7:$B$400,4)="6593")+(LEFT(Balance!$B$7:$B$400,4)="6594")+(LEFT(Balance!$B$7:$B$400,4)="6595"))*Balance!K$7:K$400) -> 0 | ... P37: =SUMPRODUCT(((LEFT(Balance!$B$7:$B$400,4)="6591")+(LEFT(Balance!$B$7:$B$400,4)="6592")+(LEFT(Balance!$B$7:$B$400,4)="6593")+(LEFT(Balance!$B$7:$B$400,4)="6594")+(LEFT(Balance!$B$7:$B$400,4)="6595"))*Balance!P$7:P$400) -> 0 | Q37: =SUM(E37:P37) -> 0
B38: 5 − Reprises d'exploitation (2) | C38: 7191-7195 | D38: =-SUMPRODUCT(((LEFT(Balance!$B$7:$B$400,4)="7191")+(LEFT(Balance!$B$7:$B$400,4)="7192")+(LEFT(Balance!$B$7:$B$400,4)="7193")+(LEFT(Balance!$B$7:$B$400,4)="7194")+(LEFT(Balance!$B$7:$B$400,4)="7195"))*Balance!D$7:D$400) -> 0 | E38: =-SUMPRODUCT(((LEFT(Balance!$B$7:$B$400,4)="7191")+(LEFT(Balance!$B$7:$B$400,4)="7192")+(LEFT(Balance!$B$7:$B$400,4)="7193")+(LEFT(Balance!$B$7:$B$400,4)="7194")+(LEFT(Balance!$B$7:$B$400,4)="7195"))*Balance!E$7:E$400) -> 0 | F38: =-SUMPRODUCT(((LEFT(Balance!$B$7:$B$400,4)="7191")+(LEFT(Balance!$B$7:$B$400,4)="7192")+(LEFT(Balance!$B$7:$B$400,4)="7193")+(LEFT(Balance!$B$7:$B$400,4)="7194")+(LEFT(Balance!$B$7:$B$400,4)="7195"))*Balance!F$7:F$400) -> 0 | G38: =-SUMPRODUCT(((LEFT(Balance!$B$7:$B$400,4)="7191")+(LEFT(Balance!$B$7:$B$400,4)="7192")+(LEFT(Balance!$B$7:$B$400,4)="7193")+(LEFT(Balance!$B$7:$B$400,4)="7194")+(LEFT(Balance!$B$7:$B$400,4)="7195"))*Balance!G$7:G$400) -> 0 | H38: =-SUMPRODUCT(((LEFT(Balance!$B$7:$B$400,4)="7191")+(LEFT(Balance!$B$7:$B$400,4)="7192")+(LEFT(Balance!$B$7:$B$400,4)="7193")+(LEFT(Balance!$B$7:$B$400,4)="7194")+(LEFT(Balance!$B$7:$B$400,4)="7195"))*Balance!H$7:H$400) -> 0 | I38: =-SUMPRODUCT(((LEFT(Balance!$B$7:$B$400,4)="7191")+(LEFT(Balance!$B$7:$B$400,4)="7192")+(LEFT(Balance!$B$7:$B$400,4)="7193")+(LEFT(Balance!$B$7:$B$400,4)="7194")+(LEFT(Balance!$B$7:$B$400,4)="7195"))*Balance!I$7:I$400) -> 0 | J38: =-SUMPRODUCT(((LEFT(Balance!$B$7:$B$400,4)="7191")+(LEFT(Balance!$B$7:$B$400,4)="7192")+(LEFT(Balance!$B$7:$B$400,4)="7193")+(LEFT(Balance!$B$7:$B$400,4)="7194")+(LEFT(Balance!$B$7:$B$400,4)="7195"))*Balance!J$7:J$400) -> 0 | K38: =-SUMPRODUCT(((LEFT(Balance!$B$7:$B$400,4)="7191")+(LEFT(Balance!$B$7:$B$400,4)="7192")+(LEFT(Balance!$B$7:$B$400,4)="7193")+(LEFT(Balance!$B$7:$B$400,4)="7194")+(LEFT(Balance!$B$7:$B$400,4)="7195"))*Balance!K$7:K$400) -> 0 | ... P38: =-SUMPRODUCT(((LEFT(Balance!$B$7:$B$400,4)="7191")+(LEFT(Balance!$B$7:$B$400,4)="7192")+(LEFT(Balance!$B$7:$B$400,4)="7193")+(LEFT(Balance!$B$7:$B$400,4)="7194")+(LEFT(Balance!$B$7:$B$400,4)="7195"))*Balance!P$7:P$400) -> 0 | Q38: =SUM(E38:P38) -> 0
B39: 6 − Reprises financières (2) | C39: 7392-7393 | D39: =-SUMPRODUCT(((LEFT(Balance!$B$7:$B$400,4)="7392")+(LEFT(Balance!$B$7:$B$400,4)="7393"))*Balance!D$7:D$400) -> 0 | E39: =-SUMPRODUCT(((LEFT(Balance!$B$7:$B$400,4)="7392")+(LEFT(Balance!$B$7:$B$400,4)="7393"))*Balance!E$7:E$400) -> 0 | F39: =-SUMPRODUCT(((LEFT(Balance!$B$7:$B$400,4)="7392")+(LEFT(Balance!$B$7:$B$400,4)="7393"))*Balance!F$7:F$400) -> 0 | G39: =-SUMPRODUCT(((LEFT(Balance!$B$7:$B$400,4)="7392")+(LEFT(Balance!$B$7:$B$400,4)="7393"))*Balance!G$7:G$400) -> 0 | H39: =-SUMPRODUCT(((LEFT(Balance!$B$7:$B$400,4)="7392")+(LEFT(Balance!$B$7:$B$400,4)="7393"))*Balance!H$7:H$400) -> 0 | I39: =-SUMPRODUCT(((LEFT(Balance!$B$7:$B$400,4)="7392")+(LEFT(Balance!$B$7:$B$400,4)="7393"))*Balance!I$7:I$400) -> 0 | J39: =-SUMPRODUCT(((LEFT(Balance!$B$7:$B$400,4)="7392")+(LEFT(Balance!$B$7:$B$400,4)="7393"))*Balance!J$7:J$400) -> 0 | K39: =-SUMPRODUCT(((LEFT(Balance!$B$7:$B$400,4)="7392")+(LEFT(Balance!$B$7:$B$400,4)="7393"))*Balance!K$7:K$400) -> 0 | ... P39: =-SUMPRODUCT(((LEFT(Balance!$B$7:$B$400,4)="7392")+(LEFT(Balance!$B$7:$B$400,4)="7393"))*Balance!P$7:P$400) -> 0 | Q39: =SUM(E39:P39) -> 0
B40: 7 − Reprises non courantes (2) (3) | C40: 757, 7591-95 | D40: =-SUMPRODUCT(((LEFT(Balance!$B$7:$B$400,3)="757")+(LEFT(Balance!$B$7:$B$400,4)="7591")+(LEFT(Balance!$B$7:$B$400,4)="7592")+(LEFT(Balance!$B$7:$B$400,4)="7593")+(LEFT(Balance!$B$7:$B$400,4)="7594")+(LEFT(Balance!$B$7:$B$400,4)="7595"))*Balance!D$7:D$400) -> 10000 | E40: =-SUMPRODUCT(((LEFT(Balance!$B$7:$B$400,3)="757")+(LEFT(Balance!$B$7:$B$400,4)="7591")+(LEFT(Balance!$B$7:$B$400,4)="7592")+(LEFT(Balance!$B$7:$B$400,4)="7593")+(LEFT(Balance!$B$7:$B$400,4)="7594")+(LEFT(Balance!$B$7:$B$400,4)="7595"))*Balance!E$7:E$400) -> 10000 | F40: =-SUMPRODUCT(((LEFT(Balance!$B$7:$B$400,3)="757")+(LEFT(Balance!$B$7:$B$400,4)="7591")+(LEFT(Balance!$B$7:$B$400,4)="7592")+(LEFT(Balance!$B$7:$B$400,4)="7593")+(LEFT(Balance!$B$7:$B$400,4)="7594")+(LEFT(Balance!$B$7:$B$400,4)="7595"))*Balance!F$7:F$400) -> 10000 | G40: =-SUMPRODUCT(((LEFT(Balance!$B$7:$B$400,3)="757")+(LEFT(Balance!$B$7:$B$400,4)="7591")+(LEFT(Balance!$B$7:$B$400,4)="7592")+(LEFT(Balance!$B$7:$B$400,4)="7593")+(LEFT(Balance!$B$7:$B$400,4)="7594")+(LEFT(Balance!$B$7:$B$400,4)="7595"))*Balance!G$7:G$400) -> 10000 | H40: =-SUMPRODUCT(((LEFT(Balance!$B$7:$B$400,3)="757")+(LEFT(Balance!$B$7:$B$400,4)="7591")+(LEFT(Balance!$B$7:$B$400,4)="7592")+(LEFT(Balance!$B$7:$B$400,4)="7593")+(LEFT(Balance!$B$7:$B$400,4)="7594")+(LEFT(Balance!$B$7:$B$400,4)="7595"))*Balance!H$7:H$400) -> 10000 | I40: =-SUMPRODUCT(((LEFT(Balance!$B$7:$B$400,3)="757")+(LEFT(Balance!$B$7:$B$400,4)="7591")+(LEFT(Balance!$B$7:$B$400,4)="7592")+(LEFT(Balance!$B$7:$B$400,4)="7593")+(LEFT(Balance!$B$7:$B$400,4)="7594")+(LEFT(Balance!$B$7:$B$400,4)="7595"))*Balance!I$7:I$400) -> 10000 | J40: =-SUMPRODUCT(((LEFT(Balance!$B$7:$B$400,3)="757")+(LEFT(Balance!$B$7:$B$400,4)="7591")+(LEFT(Balance!$B$7:$B$400,4)="7592")+(LEFT(Balance!$B$7:$B$400,4)="7593")+(LEFT(Balance!$B$7:$B$400,4)="7594")+(LEFT(Balance!$B$7:$B$400,4)="7595"))*Balance!J$7:J$400) -> 10000 | K40: =-SUMPRODUCT(((LEFT(Balance!$B$7:$B$400,3)="757")+(LEFT(Balance!$B$7:$B$400,4)="7591")+(LEFT(Balance!$B$7:$B$400,4)="7592")+(LEFT(Balance!$B$7:$B$400,4)="7593")+(LEFT(Balance!$B$7:$B$400,4)="7594")+(LEFT(Balance!$B$7:$B$400,4)="7595"))*Balance!K$7:K$400) -> 10000 | ... P40: =-SUMPRODUCT(((LEFT(Balance!$B$7:$B$400,3)="757")+(LEFT(Balance!$B$7:$B$400,4)="7591")+(LEFT(Balance!$B$7:$B$400,4)="7592")+(LEFT(Balance!$B$7:$B$400,4)="7593")+(LEFT(Balance!$B$7:$B$400,4)="7594")+(LEFT(Balance!$B$7:$B$400,4)="7595"))*Balance!P$7:P$400) -> 10000 | Q40: =SUM(E40:P40) -> 120000
B41: 8 − Produits des cessions d'immobilisations | C41: 751 | D41: =-SUMPRODUCT(((LEFT(Balance!$B$7:$B$400,3)="751"))*Balance!D$7:D$400) -> 0 | E41: =-SUMPRODUCT(((LEFT(Balance!$B$7:$B$400,3)="751"))*Balance!E$7:E$400) -> 0 | F41: =-SUMPRODUCT(((LEFT(Balance!$B$7:$B$400,3)="751"))*Balance!F$7:F$400) -> 0 | G41: =-SUMPRODUCT(((LEFT(Balance!$B$7:$B$400,3)="751"))*Balance!G$7:G$400) -> 0 | H41: =-SUMPRODUCT(((LEFT(Balance!$B$7:$B$400,3)="751"))*Balance!H$7:H$400) -> 0 | I41: =-SUMPRODUCT(((LEFT(Balance!$B$7:$B$400,3)="751"))*Balance!I$7:I$400) -> 0 | J41: =-SUMPRODUCT(((LEFT(Balance!$B$7:$B$400,3)="751"))*Balance!J$7:J$400) -> 0 | K41: =-SUMPRODUCT(((LEFT(Balance!$B$7:$B$400,3)="751"))*Balance!K$7:K$400) -> 0 | ... P41: =-SUMPRODUCT(((LEFT(Balance!$B$7:$B$400,3)="751"))*Balance!P$7:P$400) -> 0 | Q41: =SUM(E41:P41) -> 300000
B42: 9 + Valeurs nettes d'amortissements des immobilisations cédées | C42: 651 | D42: =SUMPRODUCT(((LEFT(Balance!$B$7:$B$400,3)="651"))*Balance!D$7:D$400) -> 0 | E42: =SUMPRODUCT(((LEFT(Balance!$B$7:$B$400,3)="651"))*Balance!E$7:E$400) -> 0 | F42: =SUMPRODUCT(((LEFT(Balance!$B$7:$B$400,3)="651"))*Balance!F$7:F$400) -> 0 | G42: =SUMPRODUCT(((LEFT(Balance!$B$7:$B$400,3)="651"))*Balance!G$7:G$400) -> 0 | H42: =SUMPRODUCT(((LEFT(Balance!$B$7:$B$400,3)="651"))*Balance!H$7:H$400) -> 0 | I42: =SUMPRODUCT(((LEFT(Balance!$B$7:$B$400,3)="651"))*Balance!I$7:I$400) -> 0 | J42: =SUMPRODUCT(((LEFT(Balance!$B$7:$B$400,3)="651"))*Balance!J$7:J$400) -> 0 | K42: =SUMPRODUCT(((LEFT(Balance!$B$7:$B$400,3)="651"))*Balance!K$7:K$400) -> 0 | ... P42: =SUMPRODUCT(((LEFT(Balance!$B$7:$B$400,3)="651"))*Balance!P$7:P$400) -> 0 | Q42: =SUM(E42:P42) -> 250000
...

Sheet Reporting
